Workbook

Sheet Start Here
A1: Personal Management Merit Badge — Workbook
A2: Eagle-required. Fill in the yellow cells; everything else calculates.
A4: Your info
A5: Scout name
A6: Troop #
A7: Merit badge counselor
A8: Counselor phone / email
A9: Blue card signed by Scoutmaster on
A11: Dates (Requirement 2 needs 13 consecutive weeks)
A12: START DATE (week 1 begins) | B12: 46307 | C12: Change this one cell — every week, deadline and date in the workbook moves with it. Default is next Monday.
A13: END DATE (last day of week 13) | B13: =B12+13*7-1 -> 46397
A14: Final counselor review (target) | B14: =B13+7 -> 46404
A15: Days remaining until end date | B15: =MAX(0,B13-TODAY()) -> 95
A16: Overall progress | B16: ='Requirements Tracker'!$H$3 -> 0
A18: How to use this workbook
A19: Yellow cell, blue text | B19: Your input — type here.
A20: White cell, black text | B20: Formula — don't type over it.
A21: Green cell | B21: Total / result.
A22: Example rows | B22: Rows marked “Example” show the format. Overwrite or clear them.
A24: Tabs (in the order you'll use them)
A25: Requirements Tracker | B25: Every requirement, target date, status and counselor sign-off.
A26: Req 1 Major Purchase | B26: Family purchase, savings plan, quality research, price comparison.
A27: Req 2 Budget | B27: 13-week PLANNED income, expenses and savings (2a, 2b).
A28: Req 2 Actual | B28: 13-week ACTUAL tracking — fill in every week (2c).
A29: Req 2 Compare | B29: Budget vs. actual, auto-calculated, plus your reflections (2d).
A30: Req 3-7 Discussions | B30: Notes for the money concepts, investing, insurance and credit talks.
A31: Req 4 Interest Calc | B31: Simple vs. compound interest calculator for 4c.
A32: Req 8 Time Mgmt | B32: To-do list, 7-day schedule and daily journal.
A33: Req 9 Project Plan | B33: On-paper project: goal, timeline, resources, budget.
A34: Req 10 Career | B34: Career research and cost to prepare.
A36: Requirement wording: transcribed from the Scouting America Personal Management requirements. Requirements are revised periodically — before you start, check the current version at scouting.org/merit-badges/personal-management and use whichever is in effect when you start.

Sheet Requirements Tracker
A1: Requirements Tracker
A2: Target dates are calculated from your START DATE. Set Status and get counselor initials as you go.
G3: Progress: | H3: =COUNTIF(F6:F29,"Done")/COUNTA(A6:A29) -> 0
A5: Req | B5: Requirement | C5: Work starts | D5: Target done | E5: Days left | F5: Status | G5: Date completed | H5: Counselor initials | I5: Notes
A6: 1a | B6: Choose an item that your family might want to purchase that is considered a major expense. | C6: ='Start Here'!$B$12+0 -> 46307 | D6: ='Start Here'!$B$12+6 -> 46313 | E6: =IF(F6="Done","",D6-TODAY()) -> 11 | F6: Not Started
A7: 1b | B7: Write a plan that tells how your family would save money for the purchase identified in 1a. | C7: ='Start Here'!$B$12+0 -> 46307 | D7: ='Start Here'!$B$12+13 -> 46320 | E7: =IF(F7="Done","",D7-TODAY()) -> 18 | F7: Not Started
A8: 1b(1) | B8: Discuss the plan with your merit badge counselor. | C8: ='Start Here'!$B$12+7 -> 46314 | D8: ='Start Here'!$B$12+20 -> 46327 | E8: =IF(F8="Done","",D8-TODAY()) -> 25 | F8: Not Started
A9: 1b(2) | B9: Discuss the plan with your family. | C9: ='Start Here'!$B$12+7 -> 46314 | D9: ='Start Here'!$B$12+13 -> 46320 | E9: =IF(F9="Done","",D9-TODAY()) -> 18 | F9: Not Started
A10: 1b(3) | B10: Discuss how other family needs must be considered in this plan. | C10: ='Start Here'!$B$12+7 -> 46314 | D10: ='Start Here'!$B$12+20 -> 46327 | E10: =IF(F10="Done","",D10-TODAY()) -> 25 | F10: Not Started
A11: 1c | B11: Develop a written shopping strategy for the purchase identified in 1a. | C11: ='Start Here'!$B$12+7 -> 46314 | D11: ='Start Here'!$B$12+20 -> 46327 | E11: =IF(F11="Done","",D11-TODAY()) -> 25 | F11: Not Started
A12: 1c(1) | B12: Determine the quality of the item or service (using consumer publications or ratings systems). | C12: ='Start Here'!$B$12+7 -> 46314 | D12: ='Start Here'!$B$12+20 -> 46327 | E12: =IF(F12="Done","",D12-TODAY()) -> 25 | F12: Not Started
A13: 1c(2) | B13: Comparison shop for the item. Find out where you can buy it for the best price (prices from at least two different sources). Call around; study ads. Look for a sale or discount coupon. Consider alternatives. Can you buy it used? Should you wait for a sale? | C13: ='Start Here'!$B$12+7 -> 46314 | D13: ='Start Here'!$B$12+20 -> 46327 | E13: =IF(F13="Done","",D13-TODAY()) -> 25 | F13: Not Started
A14: 2a | B14: Prepare a budget reflecting your expected income (allowance, gifts, wages), expenses, and savings for 13 consecutive weeks. | C14: ='Start Here'!$B$12+-7 -> 46300 | D14: ='Start Here'!$B$12+-1 -> 46306 | E14: =IF(F14="Done","",D14-TODAY()) -> 4 | F14: Not Started
A15: 2b | B15: Compare expected income with expected expenses. (1) If expenses exceed income, determine steps to balance your budget. (2) If income exceeds expenses, state how you would use the excess money (new goal, savings). | C15: ='Start Here'!$B$12+-7 -> 46300 | D15: ='Start Here'!$B$12+-1 -> 46306 | E15: =IF(F15="Done","",D15-TODAY()) -> 4 | F15: Not Started
A16: 2c | B16: Track and record your actual income, expenses, and savings for 13 consecutive weeks (the same 13-week period you budgeted). When complete, present the records to your counselor. | C16: ='Start Here'!$B$12+0 -> 46307 | D16: ='Start Here'!$B$12+90 -> 46397 | E16: =IF(F16="Done","",D16-TODAY()) -> 95 | F16: Not Started
A17: 2d | B17: Compare your budget with your actual income and expenses to understand when your budget worked and when it did not. With your counselor, discuss what you might do differently next time. | C17: ='Start Here'!$B$12+91 -> 46398 | D17: ='Start Here'!$B$12+97 -> 46404 | E17: =IF(F17="Done","",D17-TODAY()) -> 102 | F17: Not Started
A18: 3 | B18: Discuss with your counselor FIVE of the money concepts listed on the Req 3-7 Discussions tab. | C18: ='Start Here'!$B$12+14 -> 46321 | D18: ='Start Here'!$B$12+41 -> 46348 | E18: =IF(F18="Done","",D18-TODAY()) -> 46 | F18: Not Started
A19: 4 | B19: Explain saving vs. investing, return on investment and risk, simple vs. compound interest, diversification, and why it is important to save and invest for retirement. | C19: ='Start Here'!$B$12+21 -> 46328 | D19: ='Start Here'!$B$12+48 -> 46355 | E19: =IF(F19="Done","",D19-TODAY()) -> 53 | F19: Not Started
A20: 5 | B20: Explain what the following investments are and how each works: common stocks, mutual funds, life insurance, certificate of deposit (CD), savings account, U.S. savings bond. | C20: ='Start Here'!$B$12+28 -> 46335 | D20: ='Start Here'!$B$12+55 -> 46362 | E20: =IF(F20="Done","",D20-TODAY()) -> 60 | F20: Not Started
A21: 6 | B21: Explain why people might purchase the following types of insurance and how they work: automobile, health, homeowner's/renter's, whole life and term life. | C21: ='Start Here'!$B$12+35 -> 46342 | D21: ='Start Here'!$B$12+62 -> 46369 | E21: =IF(F21="Done","",D21-TODAY()) -> 67 | F21: Not Started
A22: 7 | B22: Explain loans, interest and APR; ways to borrow money; charge vs. debit vs. credit cards (costs, pitfalls, why paying only the minimum is unwise); credit reports; ways to reduce or eliminate debt. | C22: ='Start Here'!$B$12+42 -> 46349 | D22: ='Start Here'!$B$12+69 -> 46376 | E22: =IF(F22="Done","",D22-TODAY()) -> 74 | F22: Not Started
A23: 8a | B23: Write a “to do” list of tasks or activities that must be done in the coming week. List them in order of importance to you. | C23: ='Start Here'!$B$12+28 -> 46335 | D23: ='Start Here'!$B$12+34 -> 46341 | E23: =IF(F23="Done","",D23-TODAY()) -> 39 | F23: Not Started
A24: 8b | B24: Make a seven-day calendar or schedule with your set activities, then plan when you'll work on your to-do items between them. | C24: ='Start Here'!$B$12+28 -> 46335 | D24: ='Start Here'!$B$12+34 -> 46341 | E24: =IF(F24="Done","",D24-TODAY()) -> 39 | F24: Not Started
A25: 8c | B25: Follow the one-week schedule. Keep a daily diary/journal for each of the seven days, writing when you completed each to-do item compared to when you scheduled it. | C25: ='Start Here'!$B$12+35 -> 46342 | D25: ='Start Here'!$B$12+41 -> 46348 | E25: =IF(F25="Done","",D25-TODAY()) -> 46 | F25: Not Started
A26: 8d | B26: With your counselor, review your to-do list, schedule and journal to understand when your schedule worked and when it did not. Discuss what you might do differently next time. | C26: ='Start Here'!$B$12+42 -> 46349 | D26: ='Start Here'!$B$12+48 -> 46355 | E26: =IF(F26="Done","",D26-TODAY()) -> 53 | F26: Not Started
A27: 9 | B27: Prepare a written project plan (on paper, not a real project): (a) define the project/goal, (b) timeline, (c) description, (d) list of resources and how they help, (e) budget. Discuss it with your counselor. | C27: ='Start Here'!$B$12+49 -> 46356 | D27: ='Start Here'!$B$12+69 -> 46376 | E27: =IF(F27="Done","",D27-TODAY()) -> 74 | F27: Not Started
A28: 10 | B28: Choose a career you might want to enter after high school or college. Discuss the qualifications, education, skills and experience needed, and the costs to prepare and how you could prepare for them. | C28: ='Start Here'!$B$12+63 -> 46370 | D28: ='Start Here'!$B$12+83 -> 46390 | E28: =IF(F28="Done","",D28-TODAY()) -> 88 | F28: Not Started
A29: Final | B29: Final review with counselor — bring this workbook. Counselor signs blue card. | C29: ='Start Here'!$B$12+91 -> 46398 | D29: ='Start Here'!$B$12+104 -> 46411 | E29: =IF(F29="Done","",D29-TODAY()) -> 109 | F29: Not Started
A31: 2a/2b are due the week BEFORE your start date so the budget exists before tracking begins. Red “Days left” = overdue.

Sheet Req 1 Major Purchase
A1: Requirement 1 — Major Family Purchase
A2: 1a choose the item · 1b savings plan · 1c shopping strategy
A4: 1a. The item
A5: Item your family might buy
A6: Why your family needs/wants it
A7: Estimated cost (from best price below) | B7: =B35 -> 849
A9: 1b. Savings plan
A10: Amount already saved | B10: 0
A11: Amount family can save per month | B11: 0
A12: Amount still needed | B12: =MAX(0,B7-B10) -> 849
A13: Months to reach goal | B13: =IF(B11>0,ROUNDUP(B12/B11,0),"Enter monthly savings") -> Enter monthly savings
A14: Projected purchase date | B14: =IF(ISNUMBER(B13),EDATE('Start Here'!$B$12,B13),"")
A15: Where the savings will come from
A17: Discussion | B17: Done? | C17: Date | F17: Notes / what was said
A18: 1b(1) With merit badge counselor
A19: 1b(2) With your family
A20: 1b(3) Other family needs to consider
A22: 1c(1). Quality research (consumer publications / ratings)
A23: Source (e.g., Consumer Reports) | B23: Rating / score | C23: Pros | D23: Cons | F23: Takeaway
A24: Example: Consumer Reports | B24: 4.5 / 5 | C24: Reliable, efficient | D24: Pricier | F24: Top-rated in its class
A29: 1c(2). Comparison shopping (at least 2 sources)
A30: Store / website | B30: Price | C30: New or used? | D30: Sale / coupon $ | E30: Final price | F30: Notes (wait for a sale? alternatives?)
A31: Example: Best Buy | B31: 899 | C31: New | D31: 50 | E31: =IF(B31="","",B31-N(D31)) -> 849 | F31: Holiday sale expected in Nov.
E32: =IF(B32="","",B32-N(D32))
E33: =IF(B33="","",B33-N(D33))
E34: =IF(B34="","",B34-N(D34))
A35: Best price | B35: =IF(COUNT(E31:E34)=0,0,MIN(E31:E34)) -> 849
A36: Best source | B36: =IF(B35=0,"",INDEX(A31:A34,MATCH(B35,E31:E34,0))) -> Example: Best Buy
A37: Sources compared | B37: =COUNT(E31:E34)&IF(COUNT(E31:E34)>=2," ✓ meets 2-source minimum"," — need at least 2") -> 1 — need at least 2
A39: Written shopping strategy (1c)

Sheet Req 2 Budget
A1: Requirement 2a/2b — 13-Week PLANNED Budget
A2: Enter what you EXPECT each week. Week 1 has example amounts — replace them with yours. Rename categories in column A if needed.
A4: Week # | B4: Wk 1 | C4: Wk 2 | D4: Wk 3 | E4: Wk 4 | F4: Wk 5 | G4: Wk 6 | H4: Wk 7 | I4: Wk 8 | J4: Wk 9 | K4: Wk 10 | L4: Wk 11 | M4: Wk 12 | N4: Wk 13 | O4: 13-wk Total
A5: Week starts | B5: ='Start Here'!$B$12+0 -> 46307 | C5: ='Start Here'!$B$12+7 -> 46314 | D5: ='Start Here'!$B$12+14 -> 46321 | E5: ='Start Here'!$B$12+21 -> 46328 | F5: ='Start Here'!$B$12+28 -> 46335 | G5: ='Start Here'!$B$12+35 -> 46342 | H5: ='Start Here'!$B$12+42 -> 46349 | I5: ='Start Here'!$B$12+49 -> 46356 | J5: ='Start Here'!$B$12+56 -> 46363 | K5: ='Start Here'!$B$12+63 -> 46370 | L5: ='Start Here'!$B$12+70 -> 46377 | M5: ='Start Here'!$B$12+77 -> 46384 | N5: ='Start Here'!$B$12+84 -> 46391
A6: Week ends | B6: =B5+6 -> 46313 | C6: =C5+6 -> 46320 | D6: =D5+6 -> 46327 | E6: =E5+6 -> 46334 | F6: =F5+6 -> 46341 | G6: =G5+6 -> 46348 | H6: =H5+6 -> 46355 | I6: =I5+6 -> 46362 | ... N6: =N5+6 -> 46397
A7: INCOME
A8: Allowance | B8: 20 | O8: =SUM(B8:N8) -> 20
A9: Gifts | O9: =SUM(B9:N9) -> 0
A10: Wages / job | B10: 60 | O10: =SUM(B10:N10) -> 60
A11: Other income | O11: =SUM(B11:N11) -> 0
A12: TOTAL INCOME | B12: =SUM(B8:B11) -> 80 | C12: =SUM(C8:C11) -> 0 | D12: =SUM(D8:D11) -> 0 | E12: =SUM(E8:E11) -> 0 | F12: =SUM(F8:F11) -> 0 | G12: =SUM(G8:G11) -> 0 | H12: =SUM(H8:H11) -> 0 | I12: =SUM(I8:I11) -> 0 | ... O12: =SUM(O8:O11) -> 80
A14: EXPENSES
A15: Food & snacks | B15: 15 | O15: =SUM(B15:N15) -> 15
A16: Entertainment | B16: 15 | O16: =SUM(B16:N16) -> 15
A17: Clothing | O17: =SUM(B17:N17) -> 0
A18: Transportation / gas | B18: 10 | O18: =SUM(B18:N18) -> 10
A19: Phone / subscriptions | O19: =SUM(B19:N19) -> 0
A20: School supplies & fees | O20: =SUM(B20:N20) -> 0
A21: Scouting / activities | O21: =SUM(B21:N21) -> 0
A22: Gifts for others | O22: =SUM(B22:N22) -> 0
A23: Charity / giving | B23: 5 | O23: =SUM(B23:N23) -> 5
A24: Other expenses | O24: =SUM(B24:N24) -> 0
A25: TOTAL EXPENSES | B25: =SUM(B15:B24) -> 45 | C25: =SUM(C15:C24) -> 0 | D25: =SUM(D15:D24) -> 0 | E25: =SUM(E15:E24) -> 0 | F25: =SUM(F15:F24) -> 0 | G25: =SUM(G15:G24) -> 0 | H25: =SUM(H15:H24) -> 0 | I25: =SUM(I15:I24) -> 0 | ... O25: =SUM(O15:O24) -> 45
A27: SAVINGS
A28: Savings — general | B28: 15 | O28: =SUM(B28:N28) -> 15
A29: Savings — goal (Req 1 / other) | B29: 20 | O29: =SUM(B29:N29) -> 20
A30: TOTAL SAVINGS | B30: =SUM(B28:B29) -> 35 | C30: =SUM(C28:C29) -> 0 | D30: =SUM(D28:D29) -> 0 | E30: =SUM(E28:E29) -> 0 | F30: =SUM(F28:F29) -> 0 | G30: =SUM(G28:G29) -> 0 | H30: =SUM(H28:H29) -> 0 | I30: =SUM(I28:I29) -> 0 | ... O30: =SUM(O28:O29) -> 35
A32: Income − Expenses − Savings | B32: =B12-B25-B30 -> 0 | C32: =C12-C25-C30 -> 0 | D32: =D12-D25-D30 -> 0 | E32: =E12-E25-E30 -> 0 | F32: =F12-F25-F30 -> 0 | G32: =G12-G25-G30 -> 0 | H32: =H12-H25-H30 -> 0 | I32: =I12-I25-I30 -> 0 | ... O32: =O12-O25-O30 -> 0
A33: Running cash balance | B33: =B32 -> 0 | C33: =C32+B33 -> 0 | D33: =D32+C33 -> 0 | E33: =E32+D33 -> 0 | F33: =F32+E33 -> 0 | G33: =G32+F33 -> 0 | H33: =H32+G33 -> 0 | I33: =I32+H33 -> 0 | J33: =J32+I33 -> 0 | ... N33: =N32+M33 -> 0
A34: Running total saved | B34: =B30 -> 35 | C34: =C30+B34 -> 35 | D34: =D30+C34 -> 35 | E34: =E30+D34 -> 35 | F34: =F30+E34 -> 35 | G34: =G30+F34 -> 35 | H34: =H30+G34 -> 35 | I34: =I30+H34 -> 35 | J34: =J30+I34 -> 35 | ... N34: =N30+M34 -> 35
A36: 2b. Compare expected income with expected expenses
A37: 13-week expected income | B37: =O12 -> 80
A38: 13-week expected expenses | B38: =O25 -> 45
A39: 13-week planned savings | B39: =O30 -> 35
A40: Result | B40: =IF(B37<B38+B39,"Expenses + savings EXCEED income by "&TEXT(B38+B39-B37,"$#,##0.00")&" → answer 2b(1) below",IF(B37>B38+B39,"Income EXCEEDS expenses + savings by "&TEXT(B37-B38-B39,"$#,##0.00")&" → answer 2b(2) below","Balanced budget")) -> Balanced budget
A41: 2b(1) If expenses exceed income — steps to balance the budget
A42: 2b(2) If income exceeds expenses — how I'll use the extra (new goal, savings)

Sheet Req 2 Actual
A1: Requirement 2c — 13-Week ACTUAL Tracking
A2: Record what really came in and went out each week (same 13 weeks as the budget). Keep receipts. Update weekly — don't wait until the end.
A4: Week # | B4: Wk 1 | C4: Wk 2 | D4: Wk 3 | E4: Wk 4 | F4: Wk 5 | G4: Wk 6 | H4: Wk 7 | I4: Wk 8 | J4: Wk 9 | K4: Wk 10 | L4: Wk 11 | M4: Wk 12 | N4: Wk 13 | O4: 13-wk Total
A5: Week starts | B5: ='Start Here'!$B$12+0 -> 46307 | C5: ='Start Here'!$B$12+7 -> 46314 | D5: ='Start Here'!$B$12+14 -> 46321 | E5: ='Start Here'!$B$12+21 -> 46328 | F5: ='Start Here'!$B$12+28 -> 46335 | G5: ='Start Here'!$B$12+35 -> 46342 | H5: ='Start Here'!$B$12+42 -> 46349 | I5: ='Start Here'!$B$12+49 -> 46356 | J5: ='Start Here'!$B$12+56 -> 46363 | K5: ='Start Here'!$B$12+63 -> 46370 | L5: ='Start Here'!$B$12+70 -> 46377 | M5: ='Start Here'!$B$12+77 -> 46384 | N5: ='Start Here'!$B$12+84 -> 46391
A6: Week ends | B6: =B5+6 -> 46313 | C6: =C5+6 -> 46320 | D6: =D5+6 -> 46327 | E6: =E5+6 -> 46334 | F6: =F5+6 -> 46341 | G6: =G5+6 -> 46348 | H6: =H5+6 -> 46355 | I6: =I5+6 -> 46362 | ... N6: =N5+6 -> 46397
A7: INCOME
A8: Allowance | O8: =SUM(B8:N8) -> 0
A9: Gifts | O9: =SUM(B9:N9) -> 0
A10: Wages / job | O10: =SUM(B10:N10) -> 0
A11: Other income | O11: =SUM(B11:N11) -> 0
A12: TOTAL INCOME | B12: =SUM(B8:B11) -> 0 | C12: =SUM(C8:C11) -> 0 | D12: =SUM(D8:D11) -> 0 | E12: =SUM(E8:E11) -> 0 | F12: =SUM(F8:F11) -> 0 | G12: =SUM(G8:G11) -> 0 | H12: =SUM(H8:H11) -> 0 | I12: =SUM(I8:I11) -> 0 | ... O12: =SUM(O8:O11) -> 0
A14: EXPENSES
A15: Food & snacks | O15: =SUM(B15:N15) -> 0
A16: Entertainment | O16: =SUM(B16:N16) -> 0
A17: Clothing | O17: =SUM(B17:N17) -> 0
A18: Transportation / gas | O18: =SUM(B18:N18) -> 0
A19: Phone / subscriptions | O19: =SUM(B19:N19) -> 0
A20: School supplies & fees | O20: =SUM(B20:N20) -> 0
A21: Scouting / activities | O21: =SUM(B21:N21) -> 0
A22: Gifts for others | O22: =SUM(B22:N22) -> 0
A23: Charity / giving | O23: =SUM(B23:N23) -> 0
A24: Other expenses | O24: =SUM(B24:N24) -> 0
A25: TOTAL EXPENSES | B25: =SUM(B15:B24) -> 0 | C25: =SUM(C15:C24) -> 0 | D25: =SUM(D15:D24) -> 0 | E25: =SUM(E15:E24) -> 0 | F25: =SUM(F15:F24) -> 0 | G25: =SUM(G15:G24) -> 0 | H25: =SUM(H15:H24) -> 0 | I25: =SUM(I15:I24) -> 0 | ... O25: =SUM(O15:O24) -> 0
A27: SAVINGS
A28: Savings — general | O28: =SUM(B28:N28) -> 0
A29: Savings — goal (Req 1 / other) | O29: =SUM(B29:N29) -> 0
A30: TOTAL SAVINGS | B30: =SUM(B28:B29) -> 0 | C30: =SUM(C28:C29) -> 0 | D30: =SUM(D28:D29) -> 0 | E30: =SUM(E28:E29) -> 0 | F30: =SUM(F28:F29) -> 0 | G30: =SUM(G28:G29) -> 0 | H30: =SUM(H28:H29) -> 0 | I30: =SUM(I28:I29) -> 0 | ... O30: =SUM(O28:O29) -> 0
A32: Income − Expenses − Savings | B32: =B12-B25-B30 -> 0 | C32: =C12-C25-C30 -> 0 | D32: =D12-D25-D30 -> 0 | E32: =E12-E25-E30 -> 0 | F32: =F12-F25-F30 -> 0 | G32: =G12-G25-G30 -> 0 | H32: =H12-H25-H30 -> 0 | I32: =I12-I25-I30 -> 0 | ... O32: =O12-O25-O30 -> 0
A33: Running cash balance | B33: =B32 -> 0 | C33: =C32+B33 -> 0 | D33: =D32+C33 -> 0 | E33: =E32+D33 -> 0 | F33: =F32+E33 -> 0 | G33: =G32+F33 -> 0 | H33: =H32+G33 -> 0 | I33: =I32+H33 -> 0 | J33: =J32+I33 -> 0 | ... N33: =N32+M33 -> 0
A34: Running total saved | B34: =B30 -> 0 | C34: =C30+B34 -> 0 | D34: =D30+C34 -> 0 | E34: =E30+D34 -> 0 | F34: =F30+E34 -> 0 | G34: =G30+F34 -> 0 | H34: =H30+G34 -> 0 | I34: =I30+H34 -> 0 | J34: =J30+I34 -> 0 | ... N34: =N30+M34 -> 0
A36: Weekly log check
A37: Week recorded? | B37: =IF(COUNT(B8:B29)>0,"✓",IF(TODAY()>B6,"MISSING","")) -> ✓ | C37: =IF(COUNT(C8:C29)>0,"✓",IF(TODAY()>C6,"MISSING","")) -> ✓ | D37: =IF(COUNT(D8:D29)>0,"✓",IF(TODAY()>D6,"MISSING","")) -> ✓ | E37: =IF(COUNT(E8:E29)>0,"✓",IF(TODAY()>E6,"MISSING","")) -> ✓ | F37: =IF(COUNT(F8:F29)>0,"✓",IF(TODAY()>F6,"MISSING","")) -> ✓ | G37: =IF(COUNT(G8:G29)>0,"✓",IF(TODAY()>G6,"MISSING","")) -> ✓ | H37: =IF(COUNT(H8:H29)>0,"✓",IF(TODAY()>H6,"MISSING","")) -> ✓ | I37: =IF(COUNT(I8:I29)>0,"✓",IF(TODAY()>I6,"MISSING","")) -> ✓ | ... N37: =IF(COUNT(N8:N29)>0,"✓",IF(TODAY()>N6,"MISSING","")) -> ✓
A38: Weeks recorded | B38: =COUNTIF(B37:N37,"✓")&" of 13" -> 13 of 13

Sheet Req 2 Compare
A1: Requirement 2d — Budget vs. Actual
A2: Calculated automatically. Positive variance on income/savings = better than planned; positive variance on expenses = overspent.
A4: Category | B4: Budgeted (13 wk) | C4: Actual (13 wk) | D4: Variance (Act − Bud) | E4: % of budget | F4: Why the difference? (fill in for 2d)
A5: INCOME
A6: ='Req 2 Budget'!A8 -> Allowance | B6: ='Req 2 Budget'!O8 -> 20 | C6: ='Req 2 Actual'!O8 -> 0 | D6: =C6-B6 -> -20 | E6: =IF(B6=0,"",C6/B6) -> 0
A7: ='Req 2 Budget'!A9 -> Gifts | B7: ='Req 2 Budget'!O9 -> 0 | C7: ='Req 2 Actual'!O9 -> 0 | D7: =C7-B7 -> 0 | E7: =IF(B7=0,"",C7/B7)
A8: ='Req 2 Budget'!A10 -> Wages / job | B8: ='Req 2 Budget'!O10 -> 60 | C8: ='Req 2 Actual'!O10 -> 0 | D8: =C8-B8 -> -60 | E8: =IF(B8=0,"",C8/B8) -> 0
A9: ='Req 2 Budget'!A11 -> Other income | B9: ='Req 2 Budget'!O11 -> 0 | C9: ='Req 2 Actual'!O11 -> 0 | D9: =C9-B9 -> 0 | E9: =IF(B9=0,"",C9/B9)
A10: ='Req 2 Budget'!A12 -> TOTAL INCOME | B10: ='Req 2 Budget'!O12 -> 80 | C10: ='Req 2 Actual'!O12 -> 0 | D10: =C10-B10 -> -80 | E10: =IF(B10=0,"",C10/B10) -> 0
A12: EXPENSES
A13: ='Req 2 Budget'!A15 -> Food & snacks | B13: ='Req 2 Budget'!O15 -> 15 | C13: ='Req 2 Actual'!O15 -> 0 | D13: =C13-B13 -> -15 | E13: =IF(B13=0,"",C13/B13) -> 0
A14: ='Req 2 Budget'!A16 -> Entertainment | B14: ='Req 2 Budget'!O16 -> 15 | C14: ='Req 2 Actual'!O16 -> 0 | D14: =C14-B14 -> -15 | E14: =IF(B14=0,"",C14/B14) -> 0
A15: ='Req 2 Budget'!A17 -> Clothing | B15: ='Req 2 Budget'!O17 -> 0 | C15: ='Req 2 Actual'!O17 -> 0 | D15: =C15-B15 -> 0 | E15: =IF(B15=0,"",C15/B15)
A16: ='Req 2 Budget'!A18 -> Transportation / gas | B16: ='Req 2 Budget'!O18 -> 10 | C16: ='Req 2 Actual'!O18 -> 0 | D16: =C16-B16 -> -10 | E16: =IF(B16=0,"",C16/B16) -> 0
A17: ='Req 2 Budget'!A19 -> Phone / subscriptions | B17: ='Req 2 Budget'!O19 -> 0 | C17: ='Req 2 Actual'!O19 -> 0 | D17: =C17-B17 -> 0 | E17: =IF(B17=0,"",C17/B17)
A18: ='Req 2 Budget'!A20 -> School supplies & fees | B18: ='Req 2 Budget'!O20 -> 0 | C18: ='Req 2 Actual'!O20 -> 0 | D18: =C18-B18 -> 0 | E18: =IF(B18=0,"",C18/B18)
A19: ='Req 2 Budget'!A21 -> Scouting / activities | B19: ='Req 2 Budget'!O21 -> 0 | C19: ='Req 2 Actual'!O21 -> 0 | D19: =C19-B19 -> 0 | E19: =IF(B19=0,"",C19/B19)
A20: ='Req 2 Budget'!A22 -> Gifts for others | B20: ='Req 2 Budget'!O22 -> 0 | C20: ='Req 2 Actual'!O22 -> 0 | D20: =C20-B20 -> 0 | E20: =IF(B20=0,"",C20/B20)
A21: ='Req 2 Budget'!A23 -> Charity / giving | B21: ='Req 2 Budget'!O23 -> 5 | C21: ='Req 2 Actual'!O23 -> 0 | D21: =C21-B21 -> -5 | E21: =IF(B21=0,"",C21/B21) -> 0
A22: ='Req 2 Budget'!A24 -> Other expenses | B22: ='Req 2 Budget'!O24 -> 0 | C22: ='Req 2 Actual'!O24 -> 0 | D22: =C22-B22 -> 0 | E22: =IF(B22=0,"",C22/B22)
A23: ='Req 2 Budget'!A25 -> TOTAL EXPENSES | B23: ='Req 2 Budget'!O25 -> 45 | C23: ='Req 2 Actual'!O25 -> 0 | D23: =C23-B23 -> -45 | E23: =IF(B23=0,"",C23/B23) -> 0
A25: SAVINGS
A26: ='Req 2 Budget'!A28 -> Savings — general | B26: ='Req 2 Budget'!O28 -> 15 | C26: ='Req 2 Actual'!O28 -> 0 | D26: =C26-B26 -> -15 | E26: =IF(B26=0,"",C26/B26) -> 0
A27: ='Req 2 Budget'!A29 -> Savings — goal (Req 1 / other) | B27: ='Req 2 Budget'!O29 -> 20 | C27: ='Req 2 Actual'!O29 -> 0 | D27: =C27-B27 -> -20 | E27: =IF(B27=0,"",C27/B27) -> 0
A28: ='Req 2 Budget'!A30 -> TOTAL SAVINGS | B28: ='Req 2 Budget'!O30 -> 35 | C28: ='Req 2 Actual'!O30 -> 0 | D28: =C28-B28 -> -35 | E28: =IF(B28=0,"",C28/B28) -> 0
A30: Week | B30: Budgeted net | C30: Actual net | D30: Variance | E30: Worked? | F30: What happened that week?
A31: ="Wk 1 ("&TEXT('Req 2 Budget'!B5,"mm/dd")&")" -> Wk 1 (10/12) | B31: ='Req 2 Budget'!B32 -> 0 | C31: ='Req 2 Actual'!B32 -> 0 | D31: =C31-B31 -> 0 | E31: =IF(COUNT('Req 2 Actual'!B8:B29)=0,"",IF(C31>=0,"Yes","No — overspent")) -> Yes
A32: ="Wk 2 ("&TEXT('Req 2 Budget'!C5,"mm/dd")&")" -> Wk 2 (10/19) | B32: ='Req 2 Budget'!C32 -> 0 | C32: ='Req 2 Actual'!C32 -> 0 | D32: =C32-B32 -> 0 | E32: =IF(COUNT('Req 2 Actual'!C8:C29)=0,"",IF(C32>=0,"Yes","No — overspent")) -> Yes
A33: ="Wk 3 ("&TEXT('Req 2 Budget'!D5,"mm/dd")&")" -> Wk 3 (10/26) | B33: ='Req 2 Budget'!D32 -> 0 | C33: ='Req 2 Actual'!D32 -> 0 | D33: =C33-B33 -> 0 | E33: =IF(COUNT('Req 2 Actual'!D8:D29)=0,"",IF(C33>=0,"Yes","No — overspent")) -> Yes
A34: ="Wk 4 ("&TEXT('Req 2 Budget'!E5,"mm/dd")&")" -> Wk 4 (11/02) | B34: ='Req 2 Budget'!E32 -> 0 | C34: ='Req 2 Actual'!E32 -> 0 | D34: =C34-B34 -> 0 | E34: =IF(COUNT('Req 2 Actual'!E8:E29)=0,"",IF(C34>=0,"Yes","No — overspent")) -> Yes
A35: ="Wk 5 ("&TEXT('Req 2 Budget'!F5,"mm/dd")&")" -> Wk 5 (11/09) | B35: ='Req 2 Budget'!F32 -> 0 | C35: ='Req 2 Actual'!F32 -> 0 | D35: =C35-B35 -> 0 | E35: =IF(COUNT('Req 2 Actual'!F8:F29)=0,"",IF(C35>=0,"Yes","No — overspent")) -> Yes
A36: ="Wk 6 ("&TEXT('Req 2 Budget'!G5,"mm/dd")&")" -> Wk 6 (11/16) | B36: ='Req 2 Budget'!G32 -> 0 | C36: ='Req 2 Actual'!G32 -> 0 | D36: =C36-B36 -> 0 | E36: =IF(COUNT('Req 2 Actual'!G8:G29)=0,"",IF(C36>=0,"Yes","No — overspent")) -> Yes
A37: ="Wk 7 ("&TEXT('Req 2 Budget'!H5,"mm/dd")&")" -> Wk 7 (11/23) | B37: ='Req 2 Budget'!H32 -> 0 | C37: ='Req 2 Actual'!H32 -> 0 | D37: =C37-B37 -> 0 | E37: =IF(COUNT('Req 2 Actual'!H8:H29)=0,"",IF(C37>=0,"Yes","No — overspent")) -> Yes
A38: ="Wk 8 ("&TEXT('Req 2 Budget'!I5,"mm/dd")&")" -> Wk 8 (11/30) | B38: ='Req 2 Budget'!I32 -> 0 | C38: ='Req 2 Actual'!I32 -> 0 | D38: =C38-B38 -> 0 | E38: =IF(COUNT('Req 2 Actual'!I8:I29)=0,"",IF(C38>=0,"Yes","No — overspent")) -> Yes
A39: ="Wk 9 ("&TEXT('Req 2 Budget'!J5,"mm/dd")&")" -> Wk 9 (12/07) | B39: ='Req 2 Budget'!J32 -> 0 | C39: ='Req 2 Actual'!J32 -> 0 | D39: =C39-B39 -> 0 | E39: =IF(COUNT('Req 2 Actual'!J8:J29)=0,"",IF(C39>=0,"Yes","No — overspent")) -> Yes
A40: ="Wk 10 ("&TEXT('Req 2 Budget'!K5,"mm/dd")&")" -> Wk 10 (12/14) | B40: ='Req 2 Budget'!K32 -> 0 | C40: ='Req 2 Actual'!K32 -> 0 | D40: =C40-B40 -> 0 | E40: =IF(COUNT('Req 2 Actual'!K8:K29)=0,"",IF(C40>=0,"Yes","No — overspent")) -> Yes
A41: ="Wk 11 ("&TEXT('Req 2 Budget'!L5,"mm/dd")&")" -> Wk 11 (12/21) | B41: ='Req 2 Budget'!L32 -> 0 | C41: ='Req 2 Actual'!L32 -> 0 | D41: =C41-B41 -> 0 | E41: =IF(COUNT('Req 2 Actual'!L8:L29)=0,"",IF(C41>=0,"Yes","No — overspent")) -> Yes
A42: ="Wk 12 ("&TEXT('Req 2 Budget'!M5,"mm/dd")&")" -> Wk 12 (12/28) | B42: ='Req 2 Budget'!M32 -> 0 | C42: ='Req 2 Actual'!M32 -> 0 | D42: =C42-B42 -> 0 | E42: =IF(COUNT('Req 2 Actual'!M8:M29)=0,"",IF(C42>=0,"Yes","No — overspent")) -> Yes
A43: ="Wk 13 ("&TEXT('Req 2 Budget'!N5,"mm/dd")&")" -> Wk 13 (01/04) | B43: ='Req 2 Budget'!N32 -> 0 | C43: ='Req 2 Actual'!N32 -> 0 | D43: =C43-B43 -> 0 | E43: =IF(COUNT('Req 2 Actual'!N8:N29)=0,"",IF(C43>=0,"Yes","No — overspent")) -> Yes
A45: When did my budget WORK, and why?
...

Sheet Req 3-7 Discussions
A1: Requirements 3–7 — Discussion Prep & Notes
A2: Jot your thoughts BEFORE meeting your counselor. Your business academy / coffee shop experience is great material — use real examples.
A4: Requirement 3 — Discuss FIVE of the following concepts (mark Yes on five)
A5: Item | B5: Topic | C5: Pick | D5: My notes / real examples | E5: Date discussed
A6: 3a | B6: The emotions you feel when you receive money.
A7: 3b | B7: Your understanding of how the amount of money you have with you affects your spending habits.
A8: 3c | B8: Your thoughts when you buy something new and your thoughts about the same item three months later. Explain the concept of buyer's remorse.
A9: 3d | B9: How hobbies and interests affect your spending.
A10: 3e | B10: Your understanding of risk and how it relates to money decisions.
A11: 3f | B11: The difference between “needs” and “wants” and how they affect spending.
A12: 3g | B12: How peer pressure / advertising affects your spending.
A13: 3h | B13: Your understanding of charity and giving, and why people donate.
A14: 3i | B14: Your understanding of what it means to “live within your means.”
A15: 3j | B15: Your understanding of how money spent today affects choices tomorrow (opportunity cost).
B16: Concepts picked: | C16: =COUNTIF(C6:C15,"Yes")&" / 5" -> 0 / 5 | D16: =IF(COUNTIF(C6:C15,"Yes")=5,"✓ Ready",IF(COUNTIF(C6:C15,"Yes")>5,"Only five needed","Pick "&(5-COUNTIF(C6:C15,"Yes"))&" more")) -> Pick 5 more
B17: Note: 3a–3d are transcribed exactly; confirm the wording of 3e–3j against the current official list before your meeting.
A19: Requirement 4 — Explain to your counselor
A20: Item | B20: Topic | C20: Discussed | D20: My notes / real examples | E20: Date discussed
A21: 4a | B21: The differences between saving and investing, including reasons for using one over the other.
A22: 4b | B22: The concepts of return on investment and risk and how they are related.
A23: 4c | B23: The concepts of simple interest and compound interest (see Req 4 Interest Calc tab).
A24: 4d | B24: The concept of diversification.
A25: 4e | B25: Why it is important to save and invest for retirement.
A27: Requirement 5 — Explain what these investments are and how each works
A28: Item | B28: Topic | C28: Discussed | D28: My notes / real examples | E28: Date discussed
A29: 5a | B29: Common stocks
A30: 5b | B30: Mutual funds
A31: 5c | B31: Life insurance
A32: 5d | B32: A certificate of deposit (CD)
A33: 5e | B33: A savings account
A34: 5f | B34: A U.S. savings bond
A36: Requirement 6 — Explain why people might buy these types of insurance and how they work
A37: Item | B37: Topic | C37: Discussed | D37: My notes / real examples | E37: Date discussed
A38: 6a | B38: Automobile
A39: 6b | B39: Health
A40: 6c | B40: Homeowner's / renter's
A41: 6d | B41: Whole life and term life
A43: Requirement 7 — Explain to your counselor
A44: Item | B44: Topic | C44: Discussed | D44: My notes / real examples | E44: Date discussed
A45: 7a | B45: What a loan is, what interest is, and how the annual percentage rate (APR) measures the true cost of a loan.
...

Sheet Req 4 Interest Calc
A1: Requirement 4c — Simple vs. Compound Interest
A2: Change the yellow inputs to see how compounding grows money over time.
A4: Starting amount | B4: 1000
A5: Annual interest rate | B5: 0.05 | C5: Example rate — not a real quote
A6: Added each year | B6: 0
A7: Years | B7: 20
A9: Year | B9: Simple interest balance | C9: Compound interest balance | D9: Compounding advantage | E9: Total you put in
A10: 0 | B10: =IF(A10>$B$7,"",$B$4*(1+$B$5*A10)+$B$6*A10+$B$6*$B$5*A10*(A10-1)/2) -> 1000 | C10: =$B$4 -> 1000 | D10: =IF(A10>$B$7,"",C10-B10) -> 0 | E10: =IF(A10>$B$7,"",$B$4+$B$6*A10) -> 1000
A11: 1 | B11: =IF(A11>$B$7,"",$B$4*(1+$B$5*A11)+$B$6*A11+$B$6*$B$5*A11*(A11-1)/2) -> 1050 | C11: =IF(A11>$B$7,"",IF(A11=0,$B$4,C10*(1+$B$5)+$B$6)) -> 1050 | D11: =IF(A11>$B$7,"",C11-B11) -> 0 | E11: =IF(A11>$B$7,"",$B$4+$B$6*A11) -> 1000
A12: 2 | B12: =IF(A12>$B$7,"",$B$4*(1+$B$5*A12)+$B$6*A12+$B$6*$B$5*A12*(A12-1)/2) -> 1100 | C12: =IF(A12>$B$7,"",IF(A12=0,$B$4,C11*(1+$B$5)+$B$6)) -> 1102.5 | D12: =IF(A12>$B$7,"",C12-B12) -> 2.5 | E12: =IF(A12>$B$7,"",$B$4+$B$6*A12) -> 1000
A13: 3 | B13: =IF(A13>$B$7,"",$B$4*(1+$B$5*A13)+$B$6*A13+$B$6*$B$5*A13*(A13-1)/2) -> 1150 | C13: =IF(A13>$B$7,"",IF(A13=0,$B$4,C12*(1+$B$5)+$B$6)) -> 1157.625 | D13: =IF(A13>$B$7,"",C13-B13) -> 7.625 | E13: =IF(A13>$B$7,"",$B$4+$B$6*A13) -> 1000
A14: 4 | B14: =IF(A14>$B$7,"",$B$4*(1+$B$5*A14)+$B$6*A14+$B$6*$B$5*A14*(A14-1)/2) -> 1200 | C14: =IF(A14>$B$7,"",IF(A14=0,$B$4,C13*(1+$B$5)+$B$6)) -> 1215.5062 | D14: =IF(A14>$B$7,"",C14-B14) -> 15.50625 | E14: =IF(A14>$B$7,"",$B$4+$B$6*A14) -> 1000
A15: 5 | B15: =IF(A15>$B$7,"",$B$4*(1+$B$5*A15)+$B$6*A15+$B$6*$B$5*A15*(A15-1)/2) -> 1250 | C15: =IF(A15>$B$7,"",IF(A15=0,$B$4,C14*(1+$B$5)+$B$6)) -> 1276.2816 | D15: =IF(A15>$B$7,"",C15-B15) -> 26.281563 | E15: =IF(A15>$B$7,"",$B$4+$B$6*A15) -> 1000
A16: 6 | B16: =IF(A16>$B$7,"",$B$4*(1+$B$5*A16)+$B$6*A16+$B$6*$B$5*A16*(A16-1)/2) -> 1300 | C16: =IF(A16>$B$7,"",IF(A16=0,$B$4,C15*(1+$B$5)+$B$6)) -> 1340.0956 | D16: =IF(A16>$B$7,"",C16-B16) -> 40.095641 | E16: =IF(A16>$B$7,"",$B$4+$B$6*A16) -> 1000
A17: 7 | B17: =IF(A17>$B$7,"",$B$4*(1+$B$5*A17)+$B$6*A17+$B$6*$B$5*A17*(A17-1)/2) -> 1350 | C17: =IF(A17>$B$7,"",IF(A17=0,$B$4,C16*(1+$B$5)+$B$6)) -> 1407.1004 | D17: =IF(A17>$B$7,"",C17-B17) -> 57.100423 | E17: =IF(A17>$B$7,"",$B$4+$B$6*A17) -> 1000
A18: 8 | B18: =IF(A18>$B$7,"",$B$4*(1+$B$5*A18)+$B$6*A18+$B$6*$B$5*A18*(A18-1)/2) -> 1400 | C18: =IF(A18>$B$7,"",IF(A18=0,$B$4,C17*(1+$B$5)+$B$6)) -> 1477.4554 | D18: =IF(A18>$B$7,"",C18-B18) -> 77.455444 | E18: =IF(A18>$B$7,"",$B$4+$B$6*A18) -> 1000
A19: 9 | B19: =IF(A19>$B$7,"",$B$4*(1+$B$5*A19)+$B$6*A19+$B$6*$B$5*A19*(A19-1)/2) -> 1450 | C19: =IF(A19>$B$7,"",IF(A19=0,$B$4,C18*(1+$B$5)+$B$6)) -> 1551.3282 | D19: =IF(A19>$B$7,"",C19-B19) -> 101.32822 | E19: =IF(A19>$B$7,"",$B$4+$B$6*A19) -> 1000
A20: 10 | B20: =IF(A20>$B$7,"",$B$4*(1+$B$5*A20)+$B$6*A20+$B$6*$B$5*A20*(A20-1)/2) -> 1500 | C20: =IF(A20>$B$7,"",IF(A20=0,$B$4,C19*(1+$B$5)+$B$6)) -> 1628.8946 | D20: =IF(A20>$B$7,"",C20-B20) -> 128.89463 | E20: =IF(A20>$B$7,"",$B$4+$B$6*A20) -> 1000
A21: 11 | B21: =IF(A21>$B$7,"",$B$4*(1+$B$5*A21)+$B$6*A21+$B$6*$B$5*A21*(A21-1)/2) -> 1550 | C21: =IF(A21>$B$7,"",IF(A21=0,$B$4,C20*(1+$B$5)+$B$6)) -> 1710.3394 | D21: =IF(A21>$B$7,"",C21-B21) -> 160.33936 | E21: =IF(A21>$B$7,"",$B$4+$B$6*A21) -> 1000
A22: 12 | B22: =IF(A22>$B$7,"",$B$4*(1+$B$5*A22)+$B$6*A22+$B$6*$B$5*A22*(A22-1)/2) -> 1600 | C22: =IF(A22>$B$7,"",IF(A22=0,$B$4,C21*(1+$B$5)+$B$6)) -> 1795.8563 | D22: =IF(A22>$B$7,"",C22-B22) -> 195.85633 | E22: =IF(A22>$B$7,"",$B$4+$B$6*A22) -> 1000
... A50: 40 | B50: =IF(A50>$B$7,"",$B$4*(1+$B$5*A50)+$B$6*A50+$B$6*$B$5*A50*(A50-1)/2) | C50: =IF(A50>$B$7,"",IF(A50=0,$B$4,C49*(1+$B$5)+$B$6)) | D50: =IF(A50>$B$7,"",C50-B50) | E50: =IF(A50>$B$7,"",$B$4+$B$6*A50)
A52: Shows up to 40 years. Simple interest earns only on money deposited; compound interest also earns on past interest.
A53: Rule of 72: years to double ≈ | B53: =IF($B$5>0,72/($B$5*100),"") -> 14.4

Sheet Req 8 Time Mgmt
A1: Requirement 8 — Time Management
A2: 8a to-do list · 8b seven-day schedule · 8c follow it and keep a journal · 8d review with counselor
A4: Week begins: | B4: ='Start Here'!$B$12+35 -> 46342 | C4: Defaults to week 6 of your 13 weeks — type a different date if you want.
A6: 8a. To-do list — in order of importance
A7: Priority (1 = most) | B7: Task / activity | C7: Type | D7: Scheduled for | E7: Completed on | F7: On time?
A8: 1 | B8: Example: Chemistry lab report | C8: Homework | D8: =B4+1 -> 46343 | E8: =B4+1 -> 46343 | F8: =IF(OR(D8="",E8=""),"",IF(E8<=D8,"Yes","Late "&(E8-D8)&" day(s)")) -> Yes
F9: =IF(OR(D9="",E9=""),"",IF(E9<=D9,"Yes","Late "&(E9-D9)&" day(s)"))
F10: =IF(OR(D10="",E10=""),"",IF(E10<=D10,"Yes","Late "&(E10-D10)&" day(s)"))
F11: =IF(OR(D11="",E11=""),"",IF(E11<=D11,"Yes","Late "&(E11-D11)&" day(s)"))
F12: =IF(OR(D12="",E12=""),"",IF(E12<=D12,"Yes","Late "&(E12-D12)&" day(s)"))
F13: =IF(OR(D13="",E13=""),"",IF(E13<=D13,"Yes","Late "&(E13-D13)&" day(s)"))
F14: =IF(OR(D14="",E14=""),"",IF(E14<=D14,"Yes","Late "&(E14-D14)&" day(s)"))
F15: =IF(OR(D15="",E15=""),"",IF(E15<=D15,"Yes","Late "&(E15-D15)&" day(s)"))
F16: =IF(OR(D16="",E16=""),"",IF(E16<=D16,"Yes","Late "&(E16-D16)&" day(s)"))
F17: =IF(OR(D17="",E17=""),"",IF(E17<=D17,"Yes","Late "&(E17-D17)&" day(s)"))
F18: =IF(OR(D18="",E18=""),"",IF(E18<=D18,"Yes","Late "&(E18-D18)&" day(s)"))
F19: =IF(OR(D19="",E19=""),"",IF(E19<=D19,"Yes","Late "&(E19-D19)&" day(s)"))
A21: 8b. Seven-day schedule — put SET activities first, then fit to-do items in the gaps
A22: Time | C22: =$B$4+0 -> 46342 | D22: =$B$4+1 -> 46343 | E22: =$B$4+2 -> 46344 | F22: =$B$4+3 -> 46345 | G22: =$B$4+4 -> 46346 | H22: =$B$4+5 -> 46347 | I22: =$B$4+6 -> 46348
A23: 6 AM
A24: 7 AM
A25: 8 AM–3 PM (school)
A26: 3 PM
A27: 4 PM
A28: 5 PM
A29: 6 PM
A30: 7 PM
A31: 8 PM
A32: 9 PM
A33: 10 PM
A35: 8c. Daily journal — what you actually did vs. what you scheduled
A36: Day | B36: What I completed (and when) | C36: Scheduled vs. actual — what changed?
A37: =$B$4+0 -> 46342
A38: =$B$4+1 -> 46343
A39: =$B$4+2 -> 46344
A40: =$B$4+3 -> 46345
A41: =$B$4+4 -> 46346
A42: =$B$4+5 -> 46347
A43: =$B$4+6 -> 46348
A45: 8d. Review with counselor
...

Sheet Req 9 Project Plan
A1: Requirement 9 — Written Project Plan (on paper)
A2: Examples: a camping trip, a community service project, a school or religious event, or an annual patrol plan.
A4: 9a & 9c. Define and describe the project
A5: Project name
A6: 9a. Goal / desired outcome
A7: 9c. Description
A9: 9b. Timeline — every step from beginning to completion
A10: Step | B10: What needs to happen | C10: Start | D10: Finish | E10: Days | F10: Who's responsible
A11: 1 | B11: Example: Get approval from Scoutmaster | E11: =IF(OR(C11="",D11=""),"",D11-C11+1) | F11: Me
A12: 2 | E12: =IF(OR(C12="",D12=""),"",D12-C12+1)
A13: 3 | E13: =IF(OR(C13="",D13=""),"",D13-C13+1)
A14: 4 | E14: =IF(OR(C14="",D14=""),"",D14-C14+1)
A15: 5 | E15: =IF(OR(C15="",D15=""),"",D15-C15+1)
A16: 6 | E16: =IF(OR(C16="",D16=""),"",D16-C16+1)
A17: 7 | E17: =IF(OR(C17="",D17=""),"",D17-C17+1)
A18: 8 | E18: =IF(OR(C18="",D18=""),"",D18-C18+1)
A19: 9 | E19: =IF(OR(C19="",D19=""),"",D19-C19+1)
A20: 10 | E20: =IF(OR(C20="",D20=""),"",D20-C20+1)
A22: 9d. Resources — and how each helps reach the goal
A23: Resource (people, equipment, places, info) | B23: How it helps achieve the goal
A31: 9e. Project budget
A32: Item | B32: Category | C32: Qty | D32: Unit cost | E32: Total | F32: Funding source
A33: Example: Hot dogs (pack of 8) | B33: Food | C33: 6 | D33: 4.5 | E33: =IF(OR(C33="",D33=""),"",C33*D33) -> 27 | F33: Troop funds
E34: =IF(OR(C34="",D34=""),"",C34*D34)
E35: =IF(OR(C35="",D35=""),"",C35*D35)
E36: =IF(OR(C36="",D36=""),"",C36*D36)
E37: =IF(OR(C37="",D37=""),"",C37*D37)
E38: =IF(OR(C38="",D38=""),"",C38*D38)
E39: =IF(OR(C39="",D39=""),"",C39*D39)
E40: =IF(OR(C40="",D40=""),"",C40*D40)
E41: =IF(OR(C41="",D41=""),"",C41*D41)
E42: =IF(OR(C42="",D42=""),"",C42*D42)
D43: TOTAL | E43: =SUM(E33:E42) -> 27
A45: Discussed with counselor on

Sheet Req 10 Career
A1: Requirement 10 — Career Exploration
A3: Career I might want
A4: Why it interests me
A5: Qualifications needed
A6: Education needed (degree, certification)
A7: Skills needed
A8: Experience needed (internships, jobs)
A9: How my business academy / coffee shop finance work connects
A11: Costs to prepare for this career
A12: Cost item | B12: Estimated total
A13: Tuition
A14: Books & supplies
A15: Room & board
A16: Certifications / exams
A17: Transportation
A18: Other
A19: TOTAL | B19: =SUM(B13:B18) -> 0
A21: How I could prepare for / pay these costs (scholarships, savings, work, aid)
A22: Discussed with counselor on
